<?xml version="1.0" encoding="utf-8" ?>
<!-- This URDF was automatically created by SolidWorks to URDF Exporter! Originally created by Stephen Brawner (brawner@gmail.com) 
     Commit Version: 1.5.1-0-g916b5db  Build Version: 1.5.7152.31018
     For more information, please see http://wiki.ros.org/sw_urdf_exporter -->
<robot name="totalassembly">
    <link name="base_link">
        
	<inertial>
            <mass value="6.215" />
            <inertia ixx="0.024621" ixy="2.5781E-05" ixz="-0.00023172" iyy="0.027034" iyz="5.6467E-06" izz="0.025199" />
        </inertial>

        <visual>
            <origin xyz="0 0 0" rpy="0 0 0" />
            <geometry>
                <mesh filename="package://totalassembly/meshes/base_link.STL" />
            </geometry>
            <material name="">
                <color rgba="0.79216 0.81961 0.93333 1" />
            </material>
        </visual>
        <collision>
            <origin xyz="0 0 0" rpy="0 0 0" />
            <geometry>
                <mesh filename="package://totalassembly/meshes/base_link.STL" />
            </geometry>
        </collision>
    </link>
    <link name="arm2">
        
	<inertial>
            <mass value="0.1" />
            <inertia ixx="0.03" iyy="0.03" izz="0.03" ixy="0.0" ixz="0.0" iyz="0.0" />
        </inertial>

        <visual>
            <origin xyz="0 0 0" rpy="0 0 0" />
            <geometry>
                <mesh filename="package://totalassembly/meshes/arm2.STL" />
            </geometry>
            <material name="">
                <color rgba="0.79216 0.81961 0.93333 1" />
            </material>
        </visual>
        <collision>
            <origin xyz="0 0 0" rpy="0 0 0" />
            <geometry>
                <mesh filename="package://totalassembly/meshes/arm2.STL" />
            </geometry>
        </collision>
    </link>
    <joint name="axis1" type="revolute">
        <origin xyz="0 0 0.179" rpy="0 0 0" />
        <parent link="base_link" />
        <child link="arm2" />
        <axis xyz="0 0 -1" />
        <limit lower="-2.88" upper="2.88" effort="100" velocity="1" />
    </joint>
    <link name="arm3">
        
	<inertial>
            <mass value="0.1" />
            <inertia ixx="0.03" iyy="0.03" izz="0.03" ixy="0.0" ixz="0.0" iyz="0.0" />
        </inertial>

        <visual>
            <origin xyz="0 0 0" rpy="0 0 0" />
            <geometry>
                <mesh filename="package://totalassembly/meshes/arm3.STL" />
            </geometry>
            <material name="">
                <color rgba="0.8902 0.41176 0.13333 1" />
            </material>
        </visual>
        <collision>
            <origin xyz="0 0 0" rpy="0 0 0" />
            <geometry>
                <mesh filename="package://totalassembly/meshes/arm3.STL" />
            </geometry>
        </collision>
    </link>
    <joint name="axis2" type="revolute">
        <origin xyz="0 0.0735 0.111" rpy="0 0 0" />
        <parent link="arm2" />
        <child link="arm3" />
        <axis xyz="0 -1 0" />
        <limit lower="-1.92" upper="1.92" effort="100" velocity="1" />
    </joint>
    <link name="arm4">
        
	<inertial>
            <mass value="0.1" />
            <inertia ixx="0.03" iyy="0.03" izz="0.03" ixy="0.0" ixz="0.0" iyz="0.0" />
        </inertial>

        <visual>
            <origin xyz="0 0 0" rpy="0 0 0" />
            <geometry>
                <mesh filename="package://totalassembly/meshes/arm4.STL" />
            </geometry>
            <material name="">
                <color rgba="0.250980392156863 0.250980392156863 0.250980392156863 1" />
            </material>
        </visual>
        <collision>
            <origin xyz="0 0 0" rpy="0 0 0" />
            <geometry>
                <mesh filename="package://totalassembly/meshes/arm4.STL" />
            </geometry>
        </collision>
    </link>
    <joint name="axis3" type="revolute">
        <origin xyz="0 -0.073500000000008 0.27" rpy="0 0 0" />
        <parent link="arm3" />
        <child link="arm4" />
        <axis xyz="0 -1 0" />
        <limit lower="-1.92" upper="1.22" effort="100" velocity="1" />
    </joint>
    <link name="arm5">
        
        <inertial>
            <mass value="0.1" />
            <inertia ixx="0.03" iyy="0.03" izz="0.03" ixy="0.0" ixz="0.0" iyz="0.0" />
        </inertial>

        <visual>
            <origin xyz="0 0 0" rpy="0 0 0" />
            <geometry>
                <mesh filename="package://totalassembly/meshes/arm5.STL" />
            </geometry>
            <material name="">
                <color rgba="0.792156862745098 0.819607843137255 0.933333333333333 1" />
            </material>
        </visual>
        <collision>
            <origin xyz="0 0 0" rpy="0 0 0" />
            <geometry>
                <mesh filename="package://totalassembly/meshes/arm5.STL" />
            </geometry>
        </collision>
    </link>
    <joint name="axis4" type="revolute">
        <origin xyz="0.302000000000004 0 0.0699999999999995" rpy="0 0 0" />
        <parent link="arm4" />
        <child link="arm5" />
        <axis xyz="-1 0 0" />
        <limit lower="-2.79" upper="2.79" effort="100" velocity="1" />
    </joint>
    <link name="arm6">
        
         <inertial>
            <mass value="0.1" />
            <inertia ixx="0.03" iyy="0.03" izz="0.03" ixy="0.0" ixz="0.0" iyz="0.0" />
        </inertial>

        <visual>
            <origin xyz="0 0 0" rpy="0 0 0" />
            <geometry>
                <mesh filename="package://totalassembly/meshes/arm6.STL" />
            </geometry>
            <material name="">
                <color rgba="0.8902 0.41176 0.13333 1" />
            </material>
        </visual>
        <collision>
            <origin xyz="0 0 0" rpy="0 0 0" />
            <geometry>
                <mesh filename="package://totalassembly/meshes/arm6.STL" />
            </geometry>
        </collision>
    </link>
    <joint name="axis5" type="revolute">
        <origin xyz="0 0 0" rpy="0 0 0" />
        <parent link="arm5" />
        <child link="arm6" />
        <axis xyz="0 1 0" />
        <limit lower="-2.09" upper="2.09" effort="100" velocity="1" />
    </joint>
    <link name="gripperbase">
        
<inertial>
            <mass value="0.1" />
            <inertia ixx="0.03" iyy="0.03" izz="0.03" ixy="0.0" ixz="0.0" iyz="0.0" />
        </inertial>

        <visual>
            <origin xyz="0 0 0" rpy="0 0 0" />
            <geometry>
                <mesh filename="package://totalassembly/meshes/gripperbase.STL" />
            </geometry>
            <material name="">
                <color rgba="0.78039 0.5 0.74118 1" />
            </material>
        </visual>
        <collision>
            <origin xyz="0 0 0" rpy="0 0 0" />
            <geometry>
                <mesh filename="package://totalassembly/meshes/gripperbase.STL" />
            </geometry>
        </collision>
    </link>
    <joint name="wrist" type="revolute">
        <origin xyz="0.071999999999996 0 0" rpy="0 0 0" />
        <parent link="arm6" />
        <child link="gripperbase" />
        <axis xyz="-1 0 0" />
        <limit lower="-6.98" upper="6.98" effort="100" velocity="1" />
    </joint>
    <link name="mfingmid">
        
<inertial>
            <mass value="0.1" />
            <inertia ixx="0.03" iyy="0.03" izz="0.03" ixy="0.0" ixz="0.0" iyz="0.0" />
        </inertial>

        <visual>
            <origin xyz="0 0 0" rpy="0 0 0" />
            <geometry>
                <mesh filename="package://totalassembly/meshes/mfingmid.STL" />
            </geometry>
            <material name="">
                <color rgba="0.79216 0.2 0.93333 1" />
            </material>
        </visual>
        <collision>
            <origin xyz="0 0 0" rpy="0 0 0" />
            <geometry>
                <mesh filename="package://totalassembly/meshes/mfingmid.STL" />
            </geometry>
        </collision>
    </link>
    <joint name="mfingjoint2" type="revolute">
        <origin xyz="0.125 0 0.0419999999999996" rpy="0 -0.00154592168307366 0" />
        <parent link="gripperbase" />
        <child link="mfingmid" />
        <axis xyz="0 -1 0" />
        <limit lower="-2.4" upper="0" effort="100" velocity="1" />
    </joint>
    <link name="mfingtop">
        
        <inertial>
            <mass value="0.1" />
            <inertia ixx="0.03" iyy="0.03" izz="0.03" ixy="0.0" ixz="0.0" iyz="0.0" />
        </inertial>

        <visual>
            <origin xyz="0 0 0" rpy="0 0 0" />
            <geometry>
                <mesh filename="package://totalassembly/meshes/mfingtop.STL" />
            </geometry>
            <material name="">
                <color rgba="0.6 0.81961 0.93333 1" />
            </material>
        </visual>
        <collision>
            <origin xyz="0 0 0" rpy="0 0 0" />
            <geometry>
                <mesh filename="package://totalassembly/meshes/mfingtop.STL" />
            </geometry>
        </collision>
    </link>
    <joint name="mfingjoint3" type="revolute">
        <origin xyz="0 -0.000249999999999256 0.0500000000000007" rpy="0 0.00154592168307366 0" />
        <parent link="mfingmid" />
        <child link="mfingtop" />
        <axis xyz="0 -1 0" />
        <limit lower="-0.87" upper="0" effort="100" velocity="1" />
    </joint>
    <link name="leftmot">
        
        <inertial>
            <mass value="0.1" />
            <inertia ixx="0.03" iyy="0.03" izz="0.03" ixy="0.0" ixz="0.0" iyz="0.0" />
        </inertial>

        <visual>
            <origin xyz="0 0 0" rpy="0 0 0" />
            <geometry>
                <mesh filename="package://totalassembly/meshes/leftmot.STL" />
            </geometry>
            <material name="">
                <color rgba="0.6 0.81961 0.6 1" />
            </material>
        </visual>
        <collision>
            <origin xyz="0 0 0" rpy="0 0 0" />
            <geometry>
                <mesh filename="package://totalassembly/meshes/leftmot.STL" />
            </geometry>
        </collision>
    </link>
    <joint name="leftmotjoint" type="revolute">
        <origin xyz="0.12 -0.026667 0" rpy="0 0 0" />
        <parent link="gripperbase" />
        <child link="leftmot" />
        <axis xyz="-1 0 0" />
        <limit lower="-1.57" upper="0" effort="100" velocity="1" />
    </joint>
    <link name="lfingbottom">
        
        <inertial>
            <mass value="0.1" />
            <inertia ixx="0.03" iyy="0.03" izz="0.03" ixy="0.0" ixz="0.0" iyz="0.0" />
        </inertial>

        <visual>
            <origin xyz="0 0 0" rpy="0 0 0" />
            <geometry>
                <mesh filename="package://totalassembly/meshes/lfingbottom.STL" />
            </geometry>
            <material name="">
                <color rgba="0.79216 0.81961 0.93333 1" />
            </material>
        </visual>
        <collision>
            <origin xyz="0 0 0" rpy="0 0 0" />
            <geometry>
                <mesh filename="package://totalassembly/meshes/lfingbottom.STL" />
            </geometry>
        </collision>
    </link>
    <joint name="ljoint1" type="fixed">
        <origin xyz="0.005 0 -0.0125" rpy="0 0 0" />
        <parent link="leftmot" />
        <child link="lfingbottom" />
        <axis xyz="0 0 0" />
        <limit lower="0" upper="0" effort="0" velocity="0" />
    </joint>
    <link name="lfingmid">
        
	<inertial>
            <mass value="0.1" />
            <inertia ixx="0.03" iyy="0.03" izz="0.03" ixy="0.0" ixz="0.0" iyz="0.0" />
        </inertial>

        <visual>
            <origin xyz="0 0 0" rpy="0 0 0" />
            <geometry>
                <mesh filename="package://totalassembly/meshes/lfingmid.STL" />
            </geometry>
            <material name="">
                <color rgba="0.79216 0.2 0.93333 1" />
            </material>
        </visual>
        <collision>
            <origin xyz="0 0 0" rpy="0 0 0" />
            <geometry>
                <mesh filename="package://totalassembly/meshes/lfingmid.STL" />
            </geometry>
        </collision>
    </link>
    <joint name="ljoint2" type="revolute">
        <origin xyz="0 -0.042 0.0125" rpy="0 0 0" />
        <parent link="lfingbottom" />
        <child link="lfingmid" />
        <axis xyz="0 0 -1" />
        <limit lower="-2.4" upper="0" effort="100" velocity="1" />
    </joint>
    <link name="lfingtop">
        
        <inertial>
            <mass value="0.1" />
            <inertia ixx="0.03" iyy="0.03" izz="0.03" ixy="0.0" ixz="0.0" iyz="0.0" />
        </inertial>

        <visual>
            <origin xyz="0 0 0" rpy="0 0 0" />
            <geometry>
                <mesh filename="package://totalassembly/meshes/lfingtop.STL" />
            </geometry>
            <material name="">
                <color rgba="0.6 0.81961 0.93333 1" />
            </material>
        </visual>
        <collision>
            <origin xyz="0 0 0" rpy="0 0 0" />
            <geometry>
                <mesh filename="package://totalassembly/meshes/lfingtop.STL" />
            </geometry>
        </collision>
    </link>
    <joint name="ljoint3" type="revolute">
        <origin xyz="0 -0.05 -0.00025" rpy="0 0 0" />
        <parent link="lfingmid" />
        <child link="lfingtop" />
        <axis xyz="0 0 -1" />
        <limit lower="-0.87" upper="0" effort="100" velocity="1" />
    </joint>
    <link name="rightmot">
        
        <inertial>
            <mass value="0.1" />
            <inertia ixx="0.03" iyy="0.03" izz="0.03" ixy="0.0" ixz="0.0" iyz="0.0" />
        </inertial>

        <visual>
            <origin xyz="0 0 0" rpy="0 0 0" />
            <geometry>
                <mesh filename="package://totalassembly/meshes/rightmot.STL" />
            </geometry>
            <material name="">
                <color rgba="0.6 0.81961 0.6 1" />
            </material>
        </visual>
        <collision>
            <origin xyz="0 0 0" rpy="0 0 0" />
            <geometry>
                <mesh filename="package://totalassembly/meshes/rightmot.STL" />
            </geometry>
        </collision>
    </link>
    <joint name="rightmotjoint" type="revolute">
        <origin xyz="0.12 0.026667 0" rpy="0 0 0" />
        <parent link="gripperbase" />
        <child link="rightmot" />
        <axis xyz="1 0 0" />
        <limit lower="0" upper="0" effort="100" velocity="1" />
        <mimic joint="leftmotjoint" multiplier="1" offset="0" />
    </joint>
    <link name="rfingbottom">
        
        <inertial>
            <mass value="0.1" />
            <inertia ixx="0.03" iyy="0.03" izz="0.03" ixy="0.0" ixz="0.0" iyz="0.0" />
        </inertial>

        <visual>
            <origin xyz="0 0 0" rpy="0 0 0" />
            <geometry>
                <mesh filename="package://totalassembly/meshes/rfingbottom.STL" />
            </geometry>
            <material name="">
                <color rgba="0.79216 0.81961 0.93333 1" />
            </material>
        </visual>
        <collision>
            <origin xyz="0 0 0" rpy="0 0 0" />
            <geometry>
                <mesh filename="package://totalassembly/meshes/rfingbottom.STL" />
            </geometry>
        </collision>
    </link>
    <joint name="rjoint1" type="fixed">
        <origin xyz="0.005 0 0.0125" rpy="0 0 0" />
        <parent link="rightmot" />
        <child link="rfingbottom" />
        <axis xyz="0 0 0" />
        <limit lower="0" upper="0" effort="0" velocity="0" />
    </joint>
    <link name="rfingmid">
        
       <inertial>
            <mass value="0.1" />
            <inertia ixx="0.03" iyy="0.03" izz="0.03" ixy="0.0" ixz="0.0" iyz="0.0" />
        </inertial>

        <visual>
            <origin xyz="0 0 0" rpy="0 0 0" />
            <geometry>
                <mesh filename="package://totalassembly/meshes/rfingmid.STL" />
            </geometry>
            <material name="">
                <color rgba="0.79216 0.2 0.93333 1" />
            </material>
        </visual>
        <collision>
            <origin xyz="0 0 0" rpy="0 0 0" />
            <geometry>
                <mesh filename="package://totalassembly/meshes/rfingmid.STL" />
            </geometry>
        </collision>
    </link>
    <joint name="rjoint2" type="revolute">
        <origin xyz="0 0.0419999999999997 -0.0125000000000008" rpy="0 0 0" />
        <parent link="rfingbottom" />
        <child link="rfingmid" />
        <axis xyz="0 0 -1" />
        <limit lower="0" upper="2.4" effort="100" velocity="1" />
    </joint>
    <link name="rfingtop">
        
        <inertial>
            <mass value="0.1" />
            <inertia ixx="0.03" iyy="0.03" izz="0.03" ixy="0.0" ixz="0.0" iyz="0.0" />
        </inertial>

        <visual>
            <origin xyz="0 0 0" rpy="0 0 0" />
            <geometry>
                <mesh filename="package://totalassembly/meshes/rfingtop.STL" />
            </geometry>
            <material name="">
                <color rgba="0.6 0.81961 0.93333 1" />
            </material>
        </visual>
        <collision>
            <origin xyz="0 0 0" rpy="0 0 0" />
            <geometry>
                <mesh filename="package://totalassembly/meshes/rfingtop.STL" />
            </geometry>
        </collision>
    </link>
    <joint name="rjoint3" type="revolute">
        <origin xyz="-7.7296E-05 0.05 -0.00025" rpy="0 0 0" />
        <parent link="rfingmid" />
        <child link="rfingtop" />
        <axis xyz="0 0 -1" />
        <limit lower="0" upper="0.87" effort="100" velocity="1" />
    </joint>
    
    <transmission name="trans_axis1">
        <type>transmission_interface/SimpleTransmission</type>
        <joint name="axis1">
            <hardwareInterface>hardware_interface/PositionJointInterface</hardwareInterface>
        </joint>
        <actuator name="axis1_motor">
            <hardwareInterface>hardware_interface/PositionJointInterface</hardwareInterface>
            <mechanicalReduction>1</mechanicalReduction>
        </actuator>
    </transmission>
    <transmission name="trans_axis2">
        <type>transmission_interface/SimpleTransmission</type>
        <joint name="axis2">
            <hardwareInterface>hardware_interface/PositionJointInterface</hardwareInterface>
        </joint>
        <actuator name="axis2_motor">
            <hardwareInterface>hardware_interface/PositionJointInterface</hardwareInterface>
            <mechanicalReduction>1</mechanicalReduction>
        </actuator>
    </transmission>
    <transmission name="trans_axis3">
        <type>transmission_interface/SimpleTransmission</type>
        <joint name="axis3">
            <hardwareInterface>hardware_interface/PositionJointInterface</hardwareInterface>
        </joint>
        <actuator name="axis3_motor">
            <hardwareInterface>hardware_interface/PositionJointInterface</hardwareInterface>
            <mechanicalReduction>1</mechanicalReduction>
        </actuator>
    </transmission>
    <transmission name="trans_axis4">
        <type>transmission_interface/SimpleTransmission</type>
        <joint name="axis4">
            <hardwareInterface>hardware_interface/PositionJointInterface</hardwareInterface>
        </joint>
        <actuator name="axis4_motor">
            <hardwareInterface>hardware_interface/PositionJointInterface</hardwareInterface>
            <mechanicalReduction>1</mechanicalReduction>
        </actuator>
    </transmission>
    <transmission name="trans_axis5">
        <type>transmission_interface/SimpleTransmission</type>
        <joint name="axis5">
            <hardwareInterface>hardware_interface/PositionJointInterface</hardwareInterface>
        </joint>
        <actuator name="axis5_motor">
            <hardwareInterface>hardware_interface/PositionJointInterface</hardwareInterface>
            <mechanicalReduction>1</mechanicalReduction>
        </actuator>
    </transmission>
    <transmission name="trans_wrist">
        <type>transmission_interface/SimpleTransmission</type>
        <joint name="wrist">
            <hardwareInterface>hardware_interface/EffortJointInterface</hardwareInterface>
        </joint>
        <actuator name="wrist_motor">
            <hardwareInterface>hardware_interface/EffortJointInterface</hardwareInterface>
            <mechanicalReduction>1</mechanicalReduction>
        </actuator>
    </transmission>
    <transmission name="trans_mfingjoint2">
        <type>transmission_interface/SimpleTransmission</type>
        <joint name="mfingjoint2">
            <hardwareInterface>hardware_interface/EffortJointInterface</hardwareInterface>
        </joint>
        <actuator name="mfingjoint2_motor">
            <hardwareInterface>hardware_interface/EffortJointInterface</hardwareInterface>
            <mechanicalReduction>1</mechanicalReduction>
        </actuator>
    </transmission>
    <transmission name="trans_mfingjoint3">
        <type>transmission_interface/SimpleTransmission</type>
        <joint name="mfingjoint3">
            <hardwareInterface>hardware_interface/EffortJointInterface</hardwareInterface>
        </joint>
        <actuator name="mfingjoint3_motor">
            <hardwareInterface>hardware_interface/EffortJointInterface</hardwareInterface>
            <mechanicalReduction>1</mechanicalReduction>
        </actuator>
    </transmission>
    <transmission name="trans_leftmotjoint">
        <type>transmission_interface/SimpleTransmission</type>
        <joint name="leftmotjoint">
            <hardwareInterface>hardware_interface/EffortJointInterface</hardwareInterface>
        </joint>
        <actuator name="leftmotjoint_motor">
            <hardwareInterface>hardware_interface/EffortJointInterface</hardwareInterface>
            <mechanicalReduction>1</mechanicalReduction>
        </actuator>
    </transmission>
    <transmission name="trans_ljoint2">
        <type>transmission_interface/SimpleTransmission</type>
        <joint name="ljoint2">
            <hardwareInterface>hardware_interface/EffortJointInterface</hardwareInterface>
        </joint>
        <actuator name="ljoint2_motor">
            <hardwareInterface>hardware_interface/EffortJointInterface</hardwareInterface>
            <mechanicalReduction>1</mechanicalReduction>
        </actuator>
    </transmission>
    <transmission name="trans_ljoint3">
        <type>transmission_interface/SimpleTransmission</type>
        <joint name="ljoint3">
            <hardwareInterface>hardware_interface/EffortJointInterface</hardwareInterface>
        </joint>
        <actuator name="ljoint3_motor">
            <hardwareInterface>hardware_interface/EffortJointInterface</hardwareInterface>
            <mechanicalReduction>1</mechanicalReduction>
        </actuator>
    </transmission>
    <transmission name="trans_rightmotjoint">
        <type>transmission_interface/SimpleTransmission</type>
        <joint name="rightmotjoint">
            <hardwareInterface>hardware_interface/EffortJointInterface</hardwareInterface>
        </joint>
        <actuator name="rightmotjoint_motor">
            <hardwareInterface>hardware_interface/EffortJointInterface</hardwareInterface>
            <mechanicalReduction>1</mechanicalReduction>
        </actuator>
    </transmission>
    <transmission name="trans_rjoint2">
        <type>transmission_interface/SimpleTransmission</type>
        <joint name="rjoint2">
            <hardwareInterface>hardware_interface/EffortJointInterface</hardwareInterface>
        </joint>
        <actuator name="rjoint2_motor">
            <hardwareInterface>hardware_interface/EffortJointInterface</hardwareInterface>
            <mechanicalReduction>1</mechanicalReduction>
        </actuator>
    </transmission>
    <transmission name="trans_rjoint3">
        <type>transmission_interface/SimpleTransmission</type>
        <joint name="rjoint3">
            <hardwareInterface>hardware_interface/EffortJointInterface</hardwareInterface>
        </joint>
        <actuator name="rjoint3_motor">
            <hardwareInterface>hardware_interface/EffortJointInterface</hardwareInterface>
            <mechanicalReduction>1</mechanicalReduction>
        </actuator>
    </transmission>
    <gazebo>
        <plugin name="gazebo_ros_control" filename="libgazebo_ros_control.so">
            <robotNamespace>/</robotNamespace>
        </plugin>
    </gazebo>
    
</robot>
